import { useCallback, useState, useReducer } from "react";
import { useMountedRef } from "utils";

interface State<D> {
  error: null | Error;
  data: D | null;
  stat: "idle" | "loading" | "error" | "success";
}

const defaultInitialState: State<null> = {
  stat: "idle",
  data: null,
  error: null,
};

const defaultConfig = {
  throwOnError: false,
};

const useSafeDispatch = <T>(dispatch: (...args: T[]) => void) => {
  const mountedRef = useMountedRef();
  return useCallback(
    (...args: T[]) => (mountedRef.current ? dispatch(...args) : void 0),
    [dispatch, mountedRef]
  );
};

export const useAsync = <D>(
  initialState?: State<D>,
  initialConfig?: typeof defaultConfig
) => {
  const config = { ...defaultConfig, ...initialConfig };
  // useReducer里的action可以没有type
  const [state, dispatch] = useReducer(
    (state: State<D>, action: Partial<State<D>>) => ({
      ...state,
      ...action,
    }),
    {
      ...defaultInitialState,
      ...initialState,
    }
  );
  // action {data: Array(4), stat: "success", error: null}

  const safeDispatch = useSafeDispatch(dispatch);
  const [retry, setRetry] = useState(() => () => {});

  const setData = useCallback(
    (data: D) => {
      // console.log("data", data);
      safeDispatch({
        data,
        stat: "success",
        error: null,
      });
    },
    [safeDispatch]
  );

  const setError = useCallback(
    (error: Error) => {
      safeDispatch({
        error,
        data: null,
        stat: "error",
      });
    },
    [safeDispatch]
  );
  // run 用来触发异步请求
  const run = useCallback(
    async (promise: Promise<D>, runConfig?: { retry: () => Promise<D> }) => {
      if (!promise || !promise.then) {
        throw new Error("请传入 Promise 类型数据");
      }
      setRetry(() => () => {
        if (runConfig?.retry) {
          run(runConfig?.retry(), runConfig);
        }
      });

      safeDispatch({ stat: "loading" });
      try {
        const data = await promise;
        // console.log(data);
        setData(data);
        return data;
      } catch (error: any) {
        console.log("error", error);
        setError(error);
        // catch会消化异常，如果不主动抛出，外面是接收不到异常的
        if (config.throwOnError) return Promise.reject(error);
        return error;
      }
    },
    [config.throwOnError, safeDispatch, setData, setError]
  );

  return {
    isIdle: state.stat === "idle",
    isLoading: state.stat === "loading",
    isError: state.stat === "error",
    isSuccess: state.stat === "success",
    run,
    setData,
    setError,
    retry,
    ...state,
  };
};
